Workbook

Sheet Journey
B14: Will My Vote Count?
B15: Which steps in INEC's process cause the most public fear, and which fixes would rebuild trust before the 16 January 2027 vote?
B17: Comments read | D17: Raised a specific concern | F17: About upload, collation or courts | H17: 2023 units with no usable result
B18: =SUM(Videos!E5:E109) | D18: =COUNTA('Fears data'!$A$5:$A$1347) | F18: =SUMPRODUCT(--((('Fears data'!$Y$5:$Y$1347)+('Fears data'!$Z$5:$Z$1347)+('Fears data'!$AA$5:$AA$1347))>0))/D18 | H18: ='2023 results'!G43
B20: The journey of one vote
B21: Share of fear comments touching each step. A comment can touch several steps.
B22: Step | C22: What it is | D22: Fear comments | E22: Share | F22: What fails
B23: 1 | C23: Register | D23: =SUM('Fears data'!$U$5:$U$1347) | E23: =D23/$D$18 | F23: Permanent voter cards (PVCs) go uncollected and the register is never audited
B24: 2 | C24: Nominate | D24: =SUM('Fears data'!$V$5:$V$1347) | E24: =D24/$D$18 | F24: Party crises and pre-election cases are settled by courts and INEC recognition
B25: 3 | C25: Vote | D25: =SUM('Fears data'!$W$5:$W$1347) | E25: =D25/$D$18 | F25: Units open late and votes are bought
B26: 4 | C26: Stay safe | D26: =SUM('Fears data'!$X$5:$X$1347) | E26: =D26/$D$18 | F26: Violence and thugs keep voters away
B27: 5 | C27: Upload | D27: =SUM('Fears data'!$Y$5:$Y$1347) | E27: =D27/$D$18 | F27: Polling unit result sheets reach IReV, INEC’s public results website, late, unreadable or not at all
B28: 6 | C28: Collate | D28: =SUM('Fears data'!$Z$5:$Z$1347) | E28: =D28/$D$18 | F28: Totals change while unit results are added up at ward, local government and state centres
B29: 7 | C29: Go to court | D29: =SUM('Fears data'!$AA$5:$AA$1347) | E29: =D29/$D$18 | F29: Courts settle outcomes, and a failed upload alone does not void a result
G31: Pick a step
G32: Collate | H32: < change me
G34: Evidence
G35: =INDEX(Steps!E5:E11,MATCH(G32,Steps!C5:C11,0))
G40: Fixes for this step
G41: {=IFERROR(INDEX(Fixes!$D$5:$D$19,SMALL(IF(Fixes!$C$5:$C$19=INDEX(Steps!$B$5:$B$11,MATCH($G$32,Steps!$C$5:$C$11,0)),ROW(Fixes!$C$5:$C$19)-4),1)),"")}
G42: {=IFERROR(INDEX(Fixes!$D$5:$D$19,SMALL(IF(Fixes!$C$5:$C$19=INDEX(Steps!$B$5:$B$11,MATCH($G$32,Steps!$C$5:$C$11,0)),ROW(Fixes!$C$5:$C$19)-4),2)),"")}
G43: {=IFERROR(INDEX(Fixes!$D$5:$D$19,SMALL(IF(Fixes!$C$5:$C$19=INDEX(Steps!$B$5:$B$11,MATCH($G$32,Steps!$C$5:$C$11,0)),ROW(Fixes!$C$5:$C$19)-4),3)),"")}
B47: Read me: Amaka is an imaginary first-time voter in Enugu. Data: public YouTube comments (vidIQ), CCIJ audit of 2023 IReV result sheets, Yiaga Africa and Afrobarometer surveys. This is a reading of public fear, not a poll.

Sheet Fears data
A1: Fear comments, tagged
A2: One row per public YouTube comment that names a fear (April 2025 to October 2026). 1 = the comment names that theme. Text and author names are not stored.
A4: id | B4: month | C4: channel | D4: video_id | E4: tone | F4: rigging | G4: upload | H4: violence | I4: thugs | J4: vote_buying | K4: inec_trust | L4: apathy | M4: courts | N4: registration | O4: misinfo | P4: one_party | Q4: diaspora | R4: hardship | S4: ethnic | T4: court_pre | U4: step_1 | V4: step_2 | W4: step_3 | X4: step_4 | Y4: step_5 | Z4: step_6 | AA4: step_7
A5: b7b8c9b2ba65ff793391007386868c8c2916b6f8 | B5: 2025-04 | C5: YouTube | D5: 0 | E5: Channels Television | F5: fQ8FDQn4go0 | G5: -0.34 | H5: 0 | I5: 0 | J5: 0 | K5: 0 | L5: 0 | M5: 0 | N5: 0 | O5: 0 | P5: 0 | Q5: 0 | R5: 0 | S5: 0 | T5: 0 | U5: =IF(OR(N5=1,Q5=1),1,0) | V5: =IF(OR(T5=1,P5=1),1,0) | W5: =IF(OR(J5=1),1,0) | X5: =IF(OR(I5=1,H5=1),1,0) | Y5: =IF(OR(G5=1),1,0) | Z5: =IF(OR(F5=1),1,0) | AA5: =IF(OR(M5=1),1,0)
A6: 370073da847c9d7c4120ef0894770bd3a3fe5ab8 | B6: 2025-04 | C6: YouTube | D6: 0 | E6: Channels Television | F6: fQ8FDQn4go0 | G6: -0.469 | H6: 0 | I6: 0 | J6: 0 | K6: 0 | L6: 0 | M6: 0 | N6: 0 | O6: 0 | P6: 0 | Q6: 0 | R6: 0 | S6: 0 | T6: 0 | U6: =IF(OR(N6=1,Q6=1),1,0) | V6: =IF(OR(T6=1,P6=1),1,0) | W6: =IF(OR(J6=1),1,0) | X6: =IF(OR(I6=1,H6=1),1,0) | Y6: =IF(OR(G6=1),1,0) | Z6: =IF(OR(F6=1),1,0) | AA6: =IF(OR(M6=1),1,0)
A7: 4f1ff3f8f10cade3ee01e901678caad21fc7f54c | B7: 2025-07 | C7: YouTube | D7: 0 | E7: Channels Television | F7: -_AdFq9Q1Yk | G7: -0.602 | H7: 0 | I7: 0 | J7: 0 | K7: 0 | L7: 0 | M7: 0 | N7: 0 | O7: 0 | P7: 0 | Q7: 0 | R7: 0 | S7: 0 | T7: 0 | U7: =IF(OR(N7=1,Q7=1),1,0) | V7: =IF(OR(T7=1,P7=1),1,0) | W7: =IF(OR(J7=1),1,0) | X7: =IF(OR(I7=1,H7=1),1,0) | Y7: =IF(OR(G7=1),1,0) | Z7: =IF(OR(F7=1),1,0) | AA7: =IF(OR(M7=1),1,0)
A8: 076b451a5d31b67e4d8783f392697718cf8bf1e6 | B8: 2025-07 | C8: YouTube | D8: 0 | E8: Channels Television | F8: -_AdFq9Q1Yk | G8: 0.173 | H8: 0 | I8: 0 | J8: 0 | K8: 0 | L8: 0 | M8: 0 | N8: 0 | O8: 0 | P8: 0 | Q8: 0 | R8: 0 | S8: 0 | T8: 0 | U8: =IF(OR(N8=1,Q8=1),1,0) | V8: =IF(OR(T8=1,P8=1),1,0) | W8: =IF(OR(J8=1),1,0) | X8: =IF(OR(I8=1,H8=1),1,0) | Y8: =IF(OR(G8=1),1,0) | Z8: =IF(OR(F8=1),1,0) | AA8: =IF(OR(M8=1),1,0)
A9: 66facc8f6db83bf7a3fdd8c180a09775a85e3e84 | B9: 2025-07 | C9: YouTube | D9: 0 | E9: Channels Television | F9: -_AdFq9Q1Yk | G9: -0.902 | H9: 0 | I9: 0 | J9: 0 | K9: 0 | L9: 1 | M9: 0 | N9: 0 | O9: 0 | P9: 0 | Q9: 0 | R9: 0 | S9: 0 | T9: 0 | U9: =IF(OR(N9=1,Q9=1),1,0) | V9: =IF(OR(T9=1,P9=1),1,0) | W9: =IF(OR(J9=1),1,0) | X9: =IF(OR(I9=1,H9=1),1,0) | Y9: =IF(OR(G9=1),1,0) | Z9: =IF(OR(F9=1),1,0) | AA9: =IF(OR(M9=1),1,0)
A10: 573109bffb702355cbae675a7eea4205d419ed47 | B10: 2025-07 | C10: YouTube | D10: 0 | E10: Channels Television | F10: -_AdFq9Q1Yk | G10: 0.549 | H10: 1 | I10: 0 | J10: 0 | K10: 0 | L10: 0 | M10: 0 | N10: 0 | O10: 0 | P10: 0 | Q10: 0 | R10: 0 | S10: 0 | T10: 0 | U10: =IF(OR(N10=1,Q10=1),1,0) | V10: =IF(OR(T10=1,P10=1),1,0) | W10: =IF(OR(J10=1),1,0) | X10: =IF(OR(I10=1,H10=1),1,0) | Y10: =IF(OR(G10=1),1,0) | Z10: =IF(OR(F10=1),1,0) | AA10: =IF(OR(M10=1),1,0)
A11: 27b3ab65a51015b1487165dca7d78da264e04fd8 | B11: 2025-07 | C11: YouTube | D11: 0 | E11: Channels Television | F11: -_AdFq9Q1Yk | G11: 0.318 | H11: 1 | I11: 0 | J11: 0 | K11: 0 | L11: 0 | M11: 0 | N11: 0 | O11: 0 | P11: 0 | Q11: 0 | R11: 0 | S11: 0 | T11: 0 | U11: =IF(OR(N11=1,Q11=1),1,0) | V11: =IF(OR(T11=1,P11=1),1,0) | W11: =IF(OR(J11=1),1,0) | X11: =IF(OR(I11=1,H11=1),1,0) | Y11: =IF(OR(G11=1),1,0) | Z11: =IF(OR(F11=1),1,0) | AA11: =IF(OR(M11=1),1,0)
A12: 8dfc6972f90968e12065109bf9940e29765f2d33 | B12: 2025-07 | C12: YouTube | D12: 0 | E12: Channels Television | F12: -_AdFq9Q1Yk | G12: 0.856 | H12: 1 | I12: 0 | J12: 0 | K12: 0 | L12: 0 | M12: 0 | N12: 0 | O12: 0 | P12: 0 | Q12: 0 | R12: 0 | S12: 0 | T12: 0 | U12: =IF(OR(N12=1,Q12=1),1,0) | V12: =IF(OR(T12=1,P12=1),1,0) | W12: =IF(OR(J12=1),1,0) | X12: =IF(OR(I12=1,H12=1),1,0) | Y12: =IF(OR(G12=1),1,0) | Z12: =IF(OR(F12=1),1,0) | AA12: =IF(OR(M12=1),1,0)
A13: 4a03d302913191ba53675c76ad61ab5625ff01e1 | B13: 2025-07 | C13: YouTube | D13: 0 | E13: Channels Television | F13: -_AdFq9Q1Yk | G13: 0.604 | H13: 0 | I13: 0 | J13: 0 | K13: 0 | L13: 0 | M13: 0 | N13: 0 | O13: 1 | P13: 0 | Q13: 0 | R13: 0 | S13: 0 | T13: 0 | U13: =IF(OR(N13=1,Q13=1),1,0) | V13: =IF(OR(T13=1,P13=1),1,0) | W13: =IF(OR(J13=1),1,0) | X13: =IF(OR(I13=1,H13=1),1,0) | Y13: =IF(OR(G13=1),1,0) | Z13: =IF(OR(F13=1),1,0) | AA13: =IF(OR(M13=1),1,0)
A14: a7b5125a381b6b742846fddc09c0ba5c52fae002 | B14: 2025-07 | C14: YouTube | D14: 0 | E14: Channels Television | F14: -_AdFq9Q1Yk | G14: 0.077 | H14: 0 | I14: 0 | J14: 0 | K14: 0 | L14: 0 | M14: 0 | N14: 0 | O14: 0 | P14: 0 | Q14: 0 | R14: 0 | S14: 0 | T14: 0 | U14: =IF(OR(N14=1,Q14=1),1,0) | V14: =IF(OR(T14=1,P14=1),1,0) | W14: =IF(OR(J14=1),1,0) | X14: =IF(OR(I14=1,H14=1),1,0) | Y14: =IF(OR(G14=1),1,0) | Z14: =IF(OR(F14=1),1,0) | AA14: =IF(OR(M14=1),1,0)
A15: 22fcc50821be61005d91ac81e7958dd3312ef55a | B15: 2025-07 | C15: YouTube | D15: 0 | E15: Channels Television | F15: -_AdFq9Q1Yk | G15: 0.827 | H15: 0 | I15: 0 | J15: 0 | K15: 0 | L15: 0 | M15: 0 | N15: 0 | O15: 0 | P15: 0 | Q15: 0 | R15: 0 | S15: 0 | T15: 0 | U15: =IF(OR(N15=1,Q15=1),1,0) | V15: =IF(OR(T15=1,P15=1),1,0) | W15: =IF(OR(J15=1),1,0) | X15: =IF(OR(I15=1,H15=1),1,0) | Y15: =IF(OR(G15=1),1,0) | Z15: =IF(OR(F15=1),1,0) | AA15: =IF(OR(M15=1),1,0)
A16: 308c40a4704466c325ce25bbf32b496c399603ec | B16: 2025-07 | C16: YouTube | D16: 0 | E16: Channels Television | F16: -_AdFq9Q1Yk | G16: 0.516 | H16: 1 | I16: 0 | J16: 0 | K16: 0 | L16: 0 | M16: 0 | N16: 0 | O16: 0 | P16: 0 | Q16: 0 | R16: 0 | S16: 0 | T16: 0 | U16: =IF(OR(N16=1,Q16=1),1,0) | V16: =IF(OR(T16=1,P16=1),1,0) | W16: =IF(OR(J16=1),1,0) | X16: =IF(OR(I16=1,H16=1),1,0) | Y16: =IF(OR(G16=1),1,0) | Z16: =IF(OR(F16=1),1,0) | AA16: =IF(OR(M16=1),1,0)
... A1347: 0b64b90ffe4f7c01bd10debfb8ebfca6618d74a8 | B1347: 2026-09 | C1347: Facebook | D1347: 1 | E1347: Facebook: Facebook search: INEC BVAS 2027 | F1347: facebook:Facebook search: INEC BVAS 2027 | G1347: -0.296 | H1347: 1 | I1347: 0 | J1347: 0 | K1347: 0 | L1347: 0 | M1347: 0 | N1347: 0 | O1347: 0 | P1347: 0 | Q1347: 0 | R1347: 0 | S1347: 0 | T1347: 0 | U1347: =IF(OR(N1347=1,Q1347=1),1,0) | V1347: =IF(OR(T1347=1,P1347=1),1,0) | W1347: =IF(OR(J1347=1),1,0) | X1347: =IF(OR(I1347=1,H1347=1),1,0) | Y1347: =IF(OR(G1347=1),1,0) | Z1347: =IF(OR(F1347=1),1,0) | AA1347: =IF(OR(M1347=1),1,0)

Sheet Themes
A1: Rigging at collation is the fear people raise everywhere
A2: Share of fear comments naming each theme, against the 2023 results week on X. Formulas count the Fears data sheet.
A4: Theme | B4: INEC step | C4: Comments | D4: Share now | E4: Videos with theme | F4: 2023 share (X) | G4: Change (points)
A5: Results will be rigged | B5: 6 Collation and declaration | C5: =COUNTIF('Fears data'!$F$5:$F$1347,1) | D5: =C5/COUNTA('Fears data'!$A$5:$A$1347) | E5: 42 | F5: 0.2629 | G5: =(D5-F5)*100
A6: INEC is not neutral or able | B6: 0 INEC as an institution | C6: =COUNTIF('Fears data'!$K$5:$K$1347,1) | D6: =C6/COUNTA('Fears data'!$A$5:$A$1347) | E6: 35 | F6: n/a | G6: n/a
A7: Results will not be uploaded | B7: 5 Result upload (IReV) | C7: =COUNTIF('Fears data'!$G$5:$G$1347,1) | D7: =C7/COUNTA('Fears data'!$A$5:$A$1347) | E7: 27 | F7: 0.2105 | G7: =(D7-F7)*100
A8: The courts will decide, not voters | B8: 7 Petitions and tribunals | C8: =COUNTIF('Fears data'!$M$5:$M$1347,1) | D8: =C8/COUNTA('Fears data'!$A$5:$A$1347) | E8: 28 | F8: 0.1325 | G8: =(D8-F8)*100
A9: I cannot register or get my PVC | B9: 1 Registration and PVC | C9: =COUNTIF('Fears data'!$N$5:$N$1347,1) | D9: =C9/COUNTA('Fears data'!$A$5:$A$1347) | E9: 24 | F9: 0.0306 | G9: =(D9-F9)*100
A10: Votes will be bought | B10: 3 Voting at the polling unit | C10: =COUNTIF('Fears data'!$J$5:$J$1347,1) | D10: =C10/COUNTA('Fears data'!$A$5:$A$1347) | E10: 15 | F10: 0.0051 | G10: =(D10-F10)*100
A11: Tribe and religion will divide the vote | B11: Outside INEC | C11: =COUNTIF('Fears data'!$S$5:$S$1347,1) | D11: =C11/COUNTA('Fears data'!$A$5:$A$1347) | E11: 11 | F11: 0.053 | G11: =(D11-F11)*100
A12: Thugs will intimidate voters | B12: 4 Voting day security | C12: =COUNTIF('Fears data'!$I$5:$I$1347,1) | D12: =C12/COUNTA('Fears data'!$A$5:$A$1347) | E12: 19 | F12: 0.0301 | G12: =(D12-F12)*100
A13: Courts will decide who can run | B13: 2 Parties and candidates | C13: =COUNTIF('Fears data'!$T$5:$T$1347,1) | D13: =C13/COUNTA('Fears data'!$A$5:$A$1347) | E13: 2 | F13: 0 | G13: =(D13-F13)*100
A14: My vote will not count | B14: Turnout | C14: =COUNTIF('Fears data'!$L$5:$L$1347,1) | D14: =C14/COUNTA('Fears data'!$A$5:$A$1347) | E14: 11 | F14: 0.0049 | G14: =(D14-F14)*100
A15: Hardship makes votes cheap | B15: Outside INEC | C15: =COUNTIF('Fears data'!$R$5:$R$1347,1) | D15: =C15/COUNTA('Fears data'!$A$5:$A$1347) | E15: 6 | F15: 0.0071 | G15: =(D15-F15)*100
A16: One party will dominate | B16: 2 Parties and candidates | C16: =COUNTIF('Fears data'!$P$5:$P$1347,1) | D16: =C16/COUNTA('Fears data'!$A$5:$A$1347) | E16: 8 | F16: 0.0018 | G16: =(D16-F16)*100
A17: Fake news will mislead voters | B17: Information | C17: =COUNTIF('Fears data'!$O$5:$O$1347,1) | D17: =C17/COUNTA('Fears data'!$A$5:$A$1347) | E17: 5 | F17: 0.0078 | G17: =(D17-F17)*100
A18: Violence will stop people voting | B18: 4 Voting day security | C18: =COUNTIF('Fears data'!$H$5:$H$1347,1) | D18: =C18/COUNTA('Fears data'!$A$5:$A$1347) | E18: 8 | F18: 0.0131 | G18: =(D18-F18)*100
A19: Nigerians abroad cannot vote | B19: 1 Registration and PVC | C19: =COUNTIF('Fears data'!$Q$5:$Q$1347,1) | D19: =C19/COUNTA('Fears data'!$A$5:$A$1347) | E19: 0 | F19: 0.0089 | G19: =(D19-F19)*100
A20: Blue cells are inputs from the 2023 baseline (10,000 posts on X, 26 Feb to 14 Mar 2023, Kaggle). "Videos with theme" was counted in Python from the same rows. INEC distrust has no 2023 figure because those posts were collected by searching for INEC.

Sheet Steps
A1: INEC process steps
A2: What fails at each step and the evidence. Sources: INEC, Yiaga Africa, EU EOM 2023, Dataphyte, press reports (see Sources).
A4: Order | B4: Step | C4: Short name | D4: What fails | E4: Evidence
A5: 1 | B5: 1 Registration and PVC | C5: Register | D5: Permanent voter cards (PVCs) go uncollected and the register is never audited | E5: 6,259,229 voter cards uncollected in 2023; 18.5% uncollected in Osun 2026 (INEC)
A6: 2 | B6: 2 Parties and candidates | C6: Nominate | D6: Party crises and pre-election cases are settled by courts and INEC recognition | E6: As of March 2026, one party held 31 of 36 governorships; two main opposition parties in court disputes (2026)
A7: 3 | B7: 3 Voting at the polling unit | C7: Vote | D7: Units open late and votes are bought | E7: Officials at 27% of units by 7:30 a.m. in 2023 (Yiaga); N1,000 to N50,000 per vote in 2024 to 2026 state polls
A8: 4 | B8: 4 Voting day security | C8: Stay safe | D8: Violence and thugs keep voters away | E8: 61% say violence could stop them voting, 78% in the North-East (Yiaga, Sep 2026)
A9: 5 | B9: 5 Result upload (IReV) | C9: Upload | D9: Polling unit result sheets reach IReV, INEC’s public results website, late, unreadable or not at all | E9: 2023: 20% of presidential sheets online by noon the next day; 14.1% of units never usable online (CCIJ)
A10: 6 | B10: 6 Collation and declaration | C10: Collate | D10: Totals change while unit results are added up at ward, local government and state centres | E10: Edo 2024: Yiaga found results altered at collation in three LGAs, with more than one party involved; Ekiti 2026: over 100 unit result sheets on IReV visibly altered (Dataphyte)
A11: 7 | B11: 7 Petitions and tribunals | C11: Go to court | D11: Courts settle outcomes, and a failed upload alone does not void a result | E11: 1,196 petitions after 2023; Supreme Court (Oct 2023): IReV is a viewing portal, not a collation centre, and a failure to upload does not by itself void an election

Sheet 2023 results
A1: In 2023, one polling unit in seven had no usable result online
A2: Presidential result sheets on IReV by state. Source: Center for Collaborative Investigative Journalism audit of all polling units (GitHub).
A4: State | B4: Polling units | C4: Never uploaded | D4: Unreadable | E4: Wrong document | F4: Problem units | G4: Problem share | H4: Missing signature or stamp
A5: Abia | B5: 4062 | C5: 426 | D5: 554 | E5: 117 | F5: =SUM(C5:E5) | G5: =F5/B5 | H5: 384
A6: Adamawa | B6: 4104 | C6: 32 | D6: 169 | E6: 93 | F6: =SUM(C6:E6) | G6: =F6/B6 | H6: 526
A7: Akwa Ibom | B7: 4353 | C7: 122 | D7: 35 | E7: 15 | F7: =SUM(C7:E7) | G7: =F7/B7 | H7: 313
A8: Anambra | B8: 5720 | C8: 944 | D8: 364 | E8: 137 | F8: =SUM(C8:E8) | G8: =F8/B8 | H8: 524
A9: Bauchi | B9: 5423 | C9: 10 | D9: 141 | E9: 190 | F9: =SUM(C9:E9) | G9: =F9/B9 | H9: 737
A10: Bayelsa | B10: 2244 | C10: 78 | D10: 44 | E10: 29 | F10: =SUM(C10:E10) | G10: =F10/B10 | H10: 214
A11: Benue | B11: 5102 | C11: 264 | D11: 317 | E11: 75 | F11: =SUM(C11:E11) | G11: =F11/B11 | H11: 735
A12: Borno | B12: 5071 | C12: 33 | D12: 422 | E12: 71 | F12: =SUM(C12:E12) | G12: =F12/B12 | H12: 768
A13: Cross River | B13: 3281 | C13: 1 | D13: 137 | E13: 34 | F13: =SUM(C13:E13) | G13: =F13/B13 | H13: 407
A14: Delta | B14: 5863 | C14: 189 | D14: 761 | E14: 82 | F14: =SUM(C14:E14) | G14: =F14/B14 | H14: 551
A15: Ebonyi | B15: 2946 | C15: 24 | D15: 71 | E15: 59 | F15: =SUM(C15:E15) | G15: =F15/B15 | H15: 406
A16: Edo | B16: 4519 | C16: 9 | D16: 92 | E16: 127 | F16: =SUM(C16:E16) | G16: =F16/B16 | H16: 513
... A41: Zamfara | B41: 3529 | C41: 425 | D41: 962 | E41: 55 | F41: =SUM(C41:E41) | G41: =F41/B41 | H41: 391
A43: Nigeria | B43: =SUM(B5:B41) | C43: =SUM(C5:C41) | D43: =SUM(D5:D41) | E43: =SUM(E5:E41) | F43: =SUM(F5:F41) | G43: =F43/B43 | H43: =SUM(H5:H41)
A45: Blue cells are counts from the CCIJ dataset; black cells are formulas. "Problem" = never uploaded + unreadable + wrong document. Cancelled units are excluded from problems.

Sheet Fixes
A1: Most of the fixes need no new law and can land before 16 January
A2: Each fix is tied to a fear theme and the step it changes. Filter the table with the header arrows.
A4: Fix | B4: Theme | C4: INEC step | D4: What to do | E4: Owner | F4: Before January | G4: Needs new law | H4: Evidence
A5: F1 | B5: upload | C5: 5 Result upload (IReV) | D5: Publish every polling unit result on IReV within 2 hours of counting, with a live public tracker by state | E5: INEC | F5: Yes | G5: No | H5: 2023: 20% of presidential sheets online by noon next day; Anambra 2025 reached 99.39% in about 4 hours
A6: F2 | B6: upload | C6: 5 Result upload (IReV) | D6: Publish the list of units that did not transmit, with the stated reason, before collation starts | E6: INEC | F6: Yes | G6: No | H6: Electoral Act 2026 s.60(3) lets the paper sheet prevail when transmission fails, with no public list
A7: F3 | B7: rigging | C7: 6 Collation and declaration | D7: Check every collated total against the IReV images and publish mismatches at each collation level | E7: INEC | F7: Yes | G7: No | H7: Edo 2024: results altered at collation in three LGAs (Yiaga); Ekiti 2026: over 100 unit result sheets on IReV visibly altered (Dataphyte)
A8: F4 | B8: rigging | C8: 6 Collation and declaration | D8: Reject unreadable or wrong uploads at the device: an image quality check on the BVAS voting machine before the official leaves the unit | E8: INEC | F8: Yes | G8: No | H8: 2023: 14,252 unreadable and 3,217 wrong documents out of 176,846 units (CCIJ audit)
A9: F5 | B9: vote_buying | C9: 3 Voting at the polling unit | D9: Name high-risk units in advance and post visible EFCC and ICPC teams there; enforce the ban on showing a marked ballot | E9: INEC with EFCC and ICPC | F9: Yes | G9: No | H9: 19% received money to vote (Yiaga, Sep 2026); N1,000 to N50,000 per vote in off-cycle elections
A10: F6 | B10: violence | C10: 4 Voting day security | D10: Publish a polling unit risk map and a relocation plan for high-risk units 30 days before the vote | E10: INEC with police and ICCES | F10: Yes | G10: No | H10: 61% say violence could stop them voting; 78% in the North-East (Yiaga, Sep 2026)
A11: F7 | B11: thugs | C11: 4 Voting day security | D11: A public hotline with a case number and a published response time for incidents at polling units | E11: Police and INEC | F11: Yes | G11: No | H11: Intimidation at 6% of units in 2023 (Yiaga)
A12: F8 | B12: registration | C12: 1 Registration and PVC | D12: A voter card (PVC) status lookup by SMS and a published count of uncollected cards per polling unit, weekly | E12: INEC | F12: Yes | G12: No | H12: 6.26m uncollected PVCs in 2023; Osun 2026: 18.5% uncollected (INEC)
A13: F9 | B13: registration | C13: 1 Registration and PVC | D13: Publish the cleaned register: duplicates removed and the gap between phase totals explained | E13: INEC | F13: Yes | G13: No | H13: Phase totals 10,601,098 against 10,772,421 announced; removals unpublished
A14: F10 | B14: inec_trust | C14: 0 INEC as an institution | D14: Quarterly public scorecard of INEC service targets: opening time, upload time, PVC collection | E14: INEC with civil society | F14: Yes | G14: No | H14: 34% confident in INEC (Yiaga, Sep 2026); 16% trust (Afrobarometer 2024)
A15: F11 | B15: apathy | C15: Turnout | D15: Show first-time voters the evidence chain: their unit's result online the same night | E15: INEC and media | F15: Yes | G15: No | H15: Turnout 26.7% in 2023; 15% to 43% in recent state elections (Ekiti 36%, Osun 43%)
... A19: F15 | B19: diaspora | C19: 1 Registration and PVC | D19: Pilot diaspora voting at embassies for a later cycle | E19: National Assembly | F19: No | G19: Yes | H19: No diaspora voting in the 2026 Act; an estimated 17m Nigerians abroad (NiDCOM)
A21: Quick wins (before January, no new law) | D21: =COUNTIFS(F5:F19,"Yes",G5:G19,"No")

Sheet Videos
A1: Videos sampled
A2: Every video whose comments were read. Comment index rows come from vidIQ, which hides channel names.
A4: Video ID | B4: Channel | C4: Title | D4: Published | E4: Comments read | F4: Fear comments
A5: -_AdFq9Q1Yk | B5: Channels Television | C5: 2027: Okonkwo Backs Northerner, Says Tinubu Will Win If Coalition Presents Obi | D5: 2025-07-08 | E5: 249 | F5: =COUNTIF('Fears data'!$D$5:$D$1347,A5)
A6: 0rcLH2b9ITg | B6: Other channels (comment index) | E6: 1 | F6: =COUNTIF('Fears data'!$D$5:$D$1347,A6)
A7: 1K0T4Nn2qsU | B7: Other channels (comment index) | E7: 2 | F7: =COUNTIF('Fears data'!$D$5:$D$1347,A7)
A8: 312wEIK4KHI | B8: SaharaTV | C8: Nigerian Navy Arrests Osun Assembly APC Candidate Komolafe, Others With Rifle Ahead Of Election | D8: 2026-08-13 | E8: 118 | F8: =COUNTIF('Fears data'!$D$5:$D$1347,A8)
A9: 32K6xdF0lnA | B9: Arise News | C9: INEC Warns Public On Declaring Results+ Wike Faults Atiku+ Adebayo Slams Tinubu+ Obi At NAF|OjyOkpe | D9: 2026-10-07 | E9: 166 | F9: =COUNTIF('Fears data'!$D$5:$D$1347,A9)
A10: 4ORqpE7dbds | B10: TVC News Nigeria | C10: INEC Declares Gov. Ademola Adeleke Of Accord Party Winner Of Osun Gov'ship Election | D10: 2026-08-16 | E10: 137 | F10: =COUNTIF('Fears data'!$D$5:$D$1347,A10)
A11: 71Ylie7s4Rs | B11: Other channels (comment index) | E11: 4 | F11: =COUNTIF('Fears data'!$D$5:$D$1347,A11)
A12: 7CW8W8um2JM | B12: Other channels (comment index) | E12: 1 | F12: =COUNTIF('Fears data'!$D$5:$D$1347,A12)
A13: 7eZWhQfOozg | B13: Channels Television | C13: Election-Rigger Should Not Succeed Yakubu As INEC Chair — Datti Baba-Ahmed | D13: 2025-08-22 | E13: 101 | F13: =COUNTIF('Fears data'!$D$5:$D$1347,A13)
A14: 8pEvoYtARnY | B14: Other channels (comment index) | E14: 1 | F14: =COUNTIF('Fears data'!$D$5:$D$1347,A14)
A15: 95HiAsHA5Qs | B15: Channels Television | C15: Reps In Rowdy Session Over Motion To Rescind ‘Real-Time’ Clause In Electoral Act | D15: 2026-02-17 | E15: 133 | F15: =COUNTIF('Fears data'!$D$5:$D$1347,A15)
A16: 9Grvf3Sko0k | B16: Other channels (comment index) | E16: 1 | F16: =COUNTIF('Fears data'!$D$5:$D$1347,A16)
A17: AEi0jgyCymI | B17: Other channels (comment index) | E17: 1 | F17: =COUNTIF('Fears data'!$D$5:$D$1347,A17)
A18: Ad0HPSh6Ua8 | B18: Other channels (comment index) | E18: 2 | F18: =COUNTIF('Fears data'!$D$5:$D$1347,A18)
A19: BhwIXNKvt3A | B19: Other channels (comment index) | E19: 2 | F19: =COUNTIF('Fears data'!$D$5:$D$1347,A19)
A20: CNZzx2veECs | B20: Arise News | C20: Igini: Tinubu Shouldn't Sign the New Electoral Act | D20: 2026-02-18 | E20: 188 | F20: =COUNTIF('Fears data'!$D$5:$D$1347,A20)
A21: CXeVulc6g8k | B21: Other channels (comment index) | E21: 1 | F21: =COUNTIF('Fears data'!$D$5:$D$1347,A21)
A22: Dc33DCklqss | B22: Other channels (comment index) | E22: 1 | F22: =COUNTIF('Fears data'!$D$5:$D$1347,A22)
A23: Ei2QIFwoyqU | B23: Other channels (comment index) | E23: 1 | F23: =COUNTIF('Fears data'!$D$5:$D$1347,A23)
A24: GGw9XqiDCHo | B24: Other channels (comment index) | E24: 3 | F24: =COUNTIF('Fears data'!$D$5:$D$1347,A24)
A25: HVJZqA_wVlc | B25: Other channels (comment index) | E25: 2 | F25: =COUNTIF('Fears data'!$D$5:$D$1347,A25)
A26: KS9nNe_wrRQ | B26: Other channels (comment index) | E26: 2 | F26: =COUNTIF('Fears data'!$D$5:$D$1347,A26)
A27: MGFQHw1KOqQ | B27: Other channels (comment index) | E27: 1 | F27: =COUNTIF('Fears data'!$D$5:$D$1347,A27)
A28: OfNvlJvJUjQ | B28: Other channels (comment index) | E28: 1 | F28: =COUNTIF('Fears data'!$D$5:$D$1347,A28)
A29: PFay5n6U4mI | B29: Other channels (comment index) | E29: 1 | F29: =COUNTIF('Fears data'!$D$5:$D$1347,A29)
A30: PbtMGe-Fc9c | B30: Other channels (comment index) | E30: 1 | F30: =COUNTIF('Fears data'!$D$5:$D$1347,A30)
A31: QP1vBT5HmNs | B31: Other channels (comment index) | E31: 1 | F31: =COUNTIF('Fears data'!$D$5:$D$1347,A31)
A32: QR3zUutNa3Y | B32: Channels Television | C32: 2023: 48% Of Results On IREV Portal Did Not Come From BVAS Machine - Expert | The Morning Brief | D32: 2026-09-15 | E32: 128 | F32: =COUNTIF('Fears data'!$D$5:$D$1347,A32)
A33: QiXataJujpY | B33: Other channels (comment index) | E33: 1 | F33: =COUNTIF('Fears data'!$D$5:$D$1347,A33)
A34: Rw3H4704JBk | B34: Other channels (comment index) | E34: 1 | F34: =COUNTIF('Fears data'!$D$5:$D$1347,A34)
A35: Siagvz8Rh3s | B35: Arise News | C35: Sections 63, 138 of Electoral Act Dangerous, Sabotage Voting at Polling Level - Igini | D35: 2026-04-22 | E35: 159 | F35: =COUNTIF('Fears data'!$D$5:$D$1347,A35)
A36: SkRR82GBxWc | B36: Other channels (comment index) | E36: 2 | F36: =COUNTIF('Fears data'!$D$5:$D$1347,A36)
A37: T5Bw4cASDzk | B37: Other channels (comment index) | E37: 3 | F37: =COUNTIF('Fears data'!$D$5:$D$1347,A37)
A38: VQ_Km_CnMOk | B38: Other channels (comment index) | E38: 1 | F38: =COUNTIF('Fears data'!$D$5:$D$1347,A38)
A39: WIsZmOVRMHg | B39: Channels Television | C39: 2027: Why INEC Cannot Transmit Results Electronically | D39: 2026-02-09 | E39: 107 | F39: =COUNTIF('Fears data'!$D$5:$D$1347,A39)
A40: YwHx_tFdKZ0 | B40: Other channels (comment index) | E40: 1 | F40: =COUNTIF('Fears data'!$D$5:$D$1347,A40)
A41: Zfo8UjHjys4 | B41: Other channels (comment index) | E41: 2 | F41: =COUNTIF('Fears data'!$D$5:$D$1347,A41)
...

Sheet Sources
A1: Sources and method
A2: Every figure in this workbook traces to one of these.
A4: Survey figures
A5: Confident INEC will run credible elections | B5: 0.34 (Yiaga Africa voting intentions survey, 2026-09)
A6: Trust the electoral commission | B6: 0.16 (Afrobarometer Round 10, 2024)
A7: Say violence could stop them voting | B7: 0.61 (Yiaga Africa voting intentions survey, 2026-09)
A8: Received money to vote a certain way | B8: 0.19 (Yiaga Africa voting intentions survey, 2026-09)
A9: Presidential turnout 2023 | B9: 0.2672 (INEC via EU Election Observation Mission, 2023-02)
A10: Registered voters for 2027 | B10: 103428715.0 (INEC, 2026-10)
A11: Polling units in 2027 | B11: 176846.0 (INEC, 2026-10)
A13: YouTube comments | B13: 2,230 public comments under 70 videos (Channels Television, Arise News, TVC News, SaharaTV, four commentary channels, plus a comment index), collected through the vidIQ connector, April 2025 to October 2026. Author names were never stored.
A14: Theme tagging | B14: Keyword rules in English and Pidgin (scripts/themes.py). Hand-checked sample: about 85 to 90 percent of tags correct. INEC distrust also counts comments naming INEC with a tone score of -0.3 or lower (VADER with a Nigerian lexicon).
A15: 2023 baseline | B15: 10,000 posts on X, 26 February to 14 March 2023 (Kaggle: twitter-data-nigerian-2023-presidential-election), anonymised.
A16: 2023 result sheets | B16: Center for Collaborative Investigative Journalism, nigeria-2023-election dataset (GitHub), all 176,846 polling units.
A17: Process evidence | B17: INEC, Yiaga Africa, EU Election Observation Mission 2023, Situation Room, Dataphyte, ThisDay, Daily Trust, Channels Television; see research notes on GitHub.
A18: Limits | B18: YouTube commenters are not representative of voters. English and Pidgin only. This measures fear, not voting intention. No party or candidate is scored.
